Workbook

Sheet Master 2026-2027 US Catalog
A1: EXHAUSTIVE MASTER VEHICLE DATABASE WITH REVIEWS, PROS, CONS & IMAGE URLS (USA 2026–2027)
A2: Enterprise master vehicle catalog (455 models) complete with full mechanical specs, Car and Driver ratings, pros, cons, editorial verdicts, and high-resolution image URLs.
A3: Year | B3: Make | C3: Model / Model Group | D3: Trim / Variant | E3: Body Type | F3: Fuel Type | G3: MSRP | H3: Horsepower | I3: Torque | J3: Engine | K3: Displacement | L3: Cylinders | M3: Transmission | N3: Drivetrain | O3: MPG | P3: EV range | Q3: Battery | R3: Seating | S3: Cargo | T3: Towing | U3: C&D Rating | V3: Pros (Highs) | W3: Cons (Lows) | X3: Review Summary / Verdict | Y3: Image URL | Z3: Review URL | AA3: C&D source
A4: 2026 | B4: Acura | C4: Integra | D4: A-Spec Tech 6MT | E4: Compact Liftback | F4: Gasoline | G4: 38000 | H4: 200 | I4: 192 | J4: 1.5L Turbo I4 | K4: 1.5 | L4: 4 | M4: 6-Speed Manual | N4: FWD | O4: 30 (26/36) | P4: N/A | Q4: N/A | R4: 5 | S4: 24.3 | T4: N/A | U4: 9.0/10 | V4: • Refined performance and chassis poise • Comfortable ergonomic cabin • Comprehensive safety suite | W4: • Firm ride on optional large wheels • Option packages add up quickly • Infotainment learning curve | X4: A solid, well-rounded contender in the US compact liftback class with competitive dynamics. | Y4: https://hips.hearstapps.com/hmg-prod/images/2026-acura-integra.jpg | Z4: https://www.caranddriver.com/acura/integra | AA4: Car and Driver 10Best
A5: 2026 | B5: Acura | C5: Integra | D5: Type S | E5: High-Performance Hatch | F5: Gasoline | G5: 53795 | H5: 320 | I5: 310 | J5: 2.0L Turbo VTEC I4 | K5: 2 | L5: 4 | M5: 6-Speed Manual | N5: FWD | O5: 24 (21/28) | P5: N/A | Q5: N/A | R5: 5 | S5: 24.3 | T5: N/A | U5: 10/10 | V5: • Refined performance and chassis poise • Comfortable ergonomic cabin • Comprehensive safety suite | W5: • Firm ride on optional large wheels • Option packages add up quickly • Infotainment learning curve | X5: A solid, well-rounded contender in the US high-performance hatch class with competitive dynamics. | Y5: https://hips.hearstapps.com/hmg-prod/images/2026-acura-integra.jpg | Z5: https://www.caranddriver.com/acura/integra-type-s | AA5: Car and Driver 10Best Winner
A6: 2026 | B6: Acura | C6: TLX | D6: Technology | E6: Compact Luxury Sedan | F6: Gasoline | G6: 46595 | H6: 272 | I6: 280 | J6: 2.0L Turbo I4 | K6: 2 | L6: 4 | M6: 10-Speed Auto | N6: FWD | O6: 25 (22/31) | P6: N/A | Q6: N/A | R6: 5 | S6: 13.5 | T6: N/A | U6: 8.0/10 | V6: • Sharper handling dynamics than taller SUVs • Superior highway fuel economy • Easy maneuvering in urban spaces | W6: • Less cargo flexibility than crossovers • Lower seating hip point for ingress • Fewer AWD options | X6: A well-proportioned compact luxury sedan offering superior driving manners and efficiency over conventional crossovers. | Y6: https://hips.hearstapps.com/hmg-prod/images/2026-acura-tlx.jpg | Z6: https://www.caranddriver.com/acura/tlx | AA6: Car and Driver Review
A7: 2026 | B7: Acura | C7: TLX | D7: Type S SH-AWD | E7: Sport Sedan | F7: Gasoline | G7: 58795 | H7: 355 | I7: 354 | J7: 3.0L Turbo V6 | K7: 3 | L7: 6 | M7: 10-Speed Auto | N7: SH-AWD | O7: 21 (19/25) | P7: N/A | Q7: N/A | R7: 5 | S7: 13.5 | T7: N/A | U7: 8.5/10 | V7: • Sharper handling dynamics than taller SUVs • Superior highway fuel economy • Easy maneuvering in urban spaces | W7: • Less cargo flexibility than crossovers • Lower seating hip point for ingress • Fewer AWD options | X7: A well-proportioned sport sedan offering superior driving manners and efficiency over conventional crossovers. | Y7: https://hips.hearstapps.com/hmg-prod/images/2026-acura-tlx.jpg | Z7: https://www.caranddriver.com/acura/tlx | AA7: Car and Driver Editors' Choice
A8: 2026 | B8: Acura | C8: RDX | D8: A-Spec Advance | E8: Compact Luxury Crossover | F8: Gasoline | G8: 55450 | H8: 272 | I8: 280 | J8: 2.0L Turbo I4 | K8: 2 | L8: 4 | M8: 10-Speed Auto | N8: SH-AWD | O8: 23 (21/26) | P8: N/A | Q8: N/A | R8: 5 | S8: 29.5 | T8: 1500 | U8: 8.0/10 | V8: • Spacious passenger and cargo room • Commanding elevated driving position • Confidence-inspiring all-weather grip | W8: • Higher center of gravity than sedans • Fuel consumption under heavy load • Less engaging steering feel | X8: A highly versatile compact luxury crossover that delivers generous space, modern safety tech, and daily utility. | Y8: https://hips.hearstapps.com/hmg-prod/images/2026-acura-rdx.jpg | Z8: https://www.caranddriver.com/acura/rdx | AA8: Car and Driver Buyer's Guide
A9: 2026 | B9: Acura | C9: MDX | D9: A-Spec Advance | E9: 3-Row Luxury SUV | F9: Gasoline | G9: 63000 | H9: 290 | I9: 267 | J9: 3.5L DOHC V6 | K9: 3.5 | L9: 6 | M9: 10-Speed Auto | N9: SH-AWD | O9: 21 (19/25) | P9: N/A | Q9: N/A | R9: 7 | S9: 16.3 | T9: 5000 | U9: 8.5/10 | V9: • Spacious passenger and cargo room • Commanding elevated driving position • Confidence-inspiring all-weather grip | W9: • Higher center of gravity than sedans • Fuel consumption under heavy load • Less engaging steering feel | X9: A highly versatile 3-row luxury suv that delivers generous space, modern safety tech, and daily utility. | Y9: https://hips.hearstapps.com/hmg-prod/images/2026-acura-mdx.jpg | Z9: https://www.caranddriver.com/acura/mdx | AA9: Car and Driver Buyer's Guide
A10: 2026 | B10: Acura | C10: MDX | D10: Type S Advance | E10: 3-Row Sport Luxury SUV | F10: Gasoline | G10: 76300 | H10: 355 | I10: 354 | J10: 3.0L Turbo V6 | K10: 3 | L10: 6 | M10: 10-Speed Auto | N10: SH-AWD | O10: 19 (17/21) | P10: N/A | Q10: N/A | R10: 7 | S10: 16.3 | T10: 5000 | U10: 8.5/10 | V10: • Spacious passenger and cargo room • Commanding elevated driving position • Confidence-inspiring all-weather grip | W10: • Higher center of gravity than sedans • Fuel consumption under heavy load • Less engaging steering feel | X10: A highly versatile 3-row sport luxury suv that delivers generous space, modern safety tech, and daily utility. | Y10: https://hips.hearstapps.com/hmg-prod/images/2026-acura-mdx.jpg | Z10: https://www.caranddriver.com/acura/mdx | AA10: Car and Driver Buyer's Guide
A11: 2026 | B11: Acura | C11: ZDX | D11: Type S | E11: Mid-Size Luxury EV SUV | F11: Electric | G11: 75895 | H11: 500 | I11: 544 | J11: Dual Electric Motors | K11: N/A | L11: 0 | M11: 1-Speed Direct-Drive | N11: AWD | O11: 79 MPGe | P11: 278 | Q11: 102 | R11: 5 | S11: 28.7 | T11: 3500 | U11: 8.0/10 | V11: • Silent, instantaneous acceleration • Low center of gravity enhances stability • Zero tailpipe emissions | W11: • Highway range drops at sustained speed • Public charging network variability • Pricier initial purchase cost | X11: A compelling electric entry in the mid-size luxury ev suv segment offering smooth power delivery and advanced tech. | Y11: https://hips.hearstapps.com/hmg-prod/images/2026-acura-zdx.jpg | Z11: https://www.caranddriver.com/acura/zdx | AA11: Car and Driver Buyer's Guide
A12: 2026 | B12: Alfa Romeo | C12: Giulia | D12: Veloce Q4 | E12: Compact Luxury Sedan | F12: Gasoline | G12: 48500 | H12: 280 | I12: 306 | J12: 2.0L Turbo I4 | K12: 2 | L12: 4 | M12: 8-Speed Auto | N12: AWD | O12: 26 (23/31) | P12: N/A | Q12: N/A | R12: 5 | S12: 13 | T12: N/A | U12: 8.5/10 | V12: • Sharper handling dynamics than taller SUVs • Superior highway fuel economy • Easy maneuvering in urban spaces | W12: • Less cargo flexibility than crossovers • Lower seating hip point for ingress • Fewer AWD options | X12: A well-proportioned compact luxury sedan offering superior driving manners and efficiency over conventional crossovers. | Y12: https://hips.hearstapps.com/hmg-prod/images/2026-alfa-romeo-giulia.jpg | Z12: https://www.caranddriver.com/alfa-romeo/giulia | AA12: Car and Driver Editors' Choice
A13: 2026 | B13: Alfa Romeo | C13: Giulia | D13: Quadrifoglio | E13: Sport Sedan | F13: Gasoline | G13: 83870 | H13: 505 | I13: 443 | J13: 2.9L Twin-Turbo V6 | K13: 2.9 | L13: 6 | M13: 8-Speed Auto | N13: RWD | O13: 20 (17/25) | P13: N/A | Q13: N/A | R13: 5 | S13: 13 | T13: N/A | U13: 9.5/10 | V13: • Sharper handling dynamics than taller SUVs • Superior highway fuel economy • Easy maneuvering in urban spaces | W13: • Less cargo flexibility than crossovers • Lower seating hip point for ingress • Fewer AWD options | X13: A well-proportioned sport sedan offering superior driving manners and efficiency over conventional crossovers. | Y13: https://hips.hearstapps.com/hmg-prod/images/2026-alfa-romeo-giulia.jpg | Z13: https://www.caranddriver.com/alfa-romeo/giulia-quadrifoglio | AA13: Car and Driver Editors' Choice
A14: 2026 | B14: Alfa Romeo | C14: Stelvio | D14: Quadrifoglio | E14: Sport Luxury SUV | F14: Gasoline | G14: 89870 | H14: 505 | I14: 443 | J14: 2.9L Twin-Turbo V6 | K14: 2.9 | L14: 6 | M14: 8-Speed Auto | N14: AWD | O14: 19 (17/23) | P14: N/A | Q14: N/A | R14: 5 | S14: 18.5 | T14: 3000 | U14: 9.0/10 | V14: • Spacious passenger and cargo room • Commanding elevated driving position • Confidence-inspiring all-weather grip | W14: • Higher center of gravity than sedans • Fuel consumption under heavy load • Less engaging steering feel | X14: A highly versatile sport luxury suv that delivers generous space, modern safety tech, and daily utility. | Y14: https://hips.hearstapps.com/hmg-prod/images/2026-alfa-romeo-stelvio.jpg | Z14: https://www.caranddriver.com/alfa-romeo/stelvio-quadrifoglio | AA14: Car and Driver Editors' Choice
A15: 2026 | B15: Alfa Romeo | C15: Tonale | D15: Veloce eAWD | E15: Subcompact Luxury Crossover | F15: PHEV | G15: 49590 | H15: 285 | I15: 347 | J15: 1.3L Turbo I4 + Motor | K15: 1.3 | L15: 4 | M15: 6-Speed Auto | N15: AWD | O15: 77 MPGe / 29 Comb | P15: 33 | Q15: 15.5 | R15: 5 | S15: 22.9 | T15: 2000 | U15: 8.0/10 | V15: • Superb real-world fuel economy • Smooth electric-gas power handover • No range anxiety on long trips | W15: • Added curb weight from battery packs • Slightly compromised cargo space • eCVT engine flare during passing | X15: A finely engineered phev subcompact luxury crossover striking the optimal balance between high efficiency and long-distance practicality. | Y15: https://hips.hearstapps.com/hmg-prod/images/2026-alfa-romeo-tonale.jpg | Z15: https://www.caranddriver.com/alfa-romeo/tonale | AA15: Car and Driver Buyer's Guide
A16: 2026 | B16: Aston Martin | C16: Vantage | D16: Coupe Base | E16: Grand Tourer Coupe | F16: Gasoline | G16: 194400 | H16: 656 | I16: 590 | J16: 4.0L Twin-Turbo V8 | K16: 4 | L16: 8 | M16: 8-Speed Auto (ZF) | N16: RWD | O16: 18 (15/22) | P16: N/A | Q16: N/A | R16: 2 | S16: 10 | T16: N/A | U16: 9.0/10 | V16: • Refined performance and chassis poise • Comfortable ergonomic cabin • Comprehensive safety suite | W16: • Firm ride on optional large wheels • Option packages add up quickly • Infotainment learning curve | X16: A solid, well-rounded contender in the US grand tourer coupe class with competitive dynamics. | Y16: https://hips.hearstapps.com/hmg-prod/images/2026-aston-martin-vantage.jpg | Z16: https://www.caranddriver.com/aston-martin/vantage | AA16: Car and Driver First Drive
A17: 2026 | B17: Aston Martin | C17: DB12 | D17: Coupe Base | E17: Super Tourer | F17: Gasoline | G17: 250000 | H17: 671 | I17: 590 | J17: 4.0L Twin-Turbo V8 | K17: 4 | L17: 8 | M17: 8-Speed Auto | N17: RWD | O17: 17 (14/22) | P17: N/A | Q17: N/A | R17: 4 | S17: 9.2 | T17: N/A | U17: 9.0/10 | V17: • Refined performance and chassis poise • Comfortable ergonomic cabin • Comprehensive safety suite | W17: • Firm ride on optional large wheels • Option packages add up quickly • Infotainment learning curve | X17: A solid, well-rounded contender in the US super tourer class with competitive dynamics. | Y17: https://hips.hearstapps.com/hmg-prod/images/2026-aston-martin-db12.jpg | Z17: https://www.caranddriver.com/aston-martin/db12 | AA17: Car and Driver Review
A18: 2026 | B18: Aston Martin | C18: Vanquish | D18: Base V12 | E18: Flagship Super GT | F18: Gasoline | G18: 429000 | H18: 824 | I18: 738 | J18: 5.2L Twin-Turbo V12 | K18: 5.2 | L18: 12 | M18: 8-Speed Auto | N18: RWD | O18: 14 (12/18 Est) | P18: N/A | Q18: N/A | R18: 2 | S18: 8.8 | T18: N/A | U18: 9.5/10 | V18: • Refined performance and chassis poise • Comfortable ergonomic cabin • Comprehensive safety suite | W18: • Firm ride on optional large wheels • Option packages add up quickly • Infotainment learning curve | X18: A solid, well-rounded contender in the US flagship super gt class with competitive dynamics. | Y18: https://hips.hearstapps.com/hmg-prod/images/2026-aston-martin-vanquish.jpg | Z18: https://www.caranddriver.com/aston-martin/vanquish | AA18: Car and Driver First Look
A19: 2026 | B19: Aston Martin | C19: DBX | D19: DBX707 | E19: Ultra-Luxury SUV | F19: Gasoline | G19: 253000 | H19: 697 | I19: 663 | J19: 4.0L Twin-Turbo AMG V8 | K19: 4 | L19: 8 | M19: 9-Speed Wet-Clutch | N19: AWD | O19: 17 (15/20) | P19: N/A | Q19: N/A | R19: 5 | S19: 22.5 | T19: 5940 | U19: 9.0/10 | V19: • Spacious passenger and cargo room • Commanding elevated driving position • Confidence-inspiring all-weather grip | W19: • Higher center of gravity than sedans • Fuel consumption under heavy load • Less engaging steering feel | X19: A highly versatile ultra-luxury suv that delivers generous space, modern safety tech, and daily utility. | Y19: https://hips.hearstapps.com/hmg-prod/images/2026-aston-martin-dbx.jpg | Z19: https://www.caranddriver.com/aston-martin/dbx | AA19: Car and Driver Buyer's Guide
A20: 2026 | B20: Audi | C20: A3 | D20: Premium 40 TFSI | E20: Subcompact Luxury Sedan | F20: Mild Hybrid | G20: 40000 | H20: 201 | I20: 221 | J20: 2.0L Turbo I4 48V | K20: 2 | L20: 4 | M20: 7-Speed DSG | N20: AWD | O20: 30 (27/35) | P20: N/A | Q20: N/A | R20: 5 | S20: 10.9 | T20: N/A | U20: 9.0/10 | V20: • Superb real-world fuel economy • Smooth electric-gas power handover • No range anxiety on long trips | W20: • Added curb weight from battery packs • Slightly compromised cargo space • eCVT engine flare during passing | X20: A finely engineered mild hybrid subcompact luxury sedan striking the optimal balance between high efficiency and long-distance practicality. | Y20: https://hips.hearstapps.com/hmg-prod/images/2026-audi-a3.jpg | Z20: https://www.caranddriver.com/audi/a3 | AA20: Car and Driver Editors' Choice
A21: 2026 | B21: Audi | C21: S3 | D21: Premium Plus | E21: Sport Compact Sedan | F21: Gasoline | G21: 49500 | H21: 328 | I21: 310 | J21: 2.0L Turbo I4 | K21: 2 | L21: 4 | M21: 7-Speed DSG | N21: quattro AWD | O21: 26 (23/32) | P21: N/A | Q21: N/A | R21: 5 | S21: 8.3 | T21: N/A | U21: 9.0/10 | V21: • Sharper handling dynamics than taller SUVs • Superior highway fuel economy • Easy maneuvering in urban spaces | W21: • Less cargo flexibility than crossovers • Lower seating hip point for ingress • Fewer AWD options | X21: A well-proportioned sport compact sedan offering superior driving manners and efficiency over conventional crossovers. | Y21: https://hips.hearstapps.com/hmg-prod/images/2026-audi-s3.jpg | Z21: https://www.caranddriver.com/audi/s3 | AA21: Car and Driver Editors' Choice
A22: 2026 | B22: Audi | C22: RS3 | D22: Sedan Base | E22: High-Perf Compact Sedan | F22: Gasoline | G22: 63500 | H22: 401 | I22: 369 | J22: 2.5L Turbo Inline-5 | K22: 2.5 | L22: 5 | M22: 7-Speed DSG | N22: quattro AWD | O22: 23 (19/29) | P22: N/A | Q22: N/A | R22: 5 | S22: 8.3 | T22: N/A | U22: 9.5/10 | V22: • Sharper handling dynamics than taller SUVs • Superior highway fuel economy • Easy maneuvering in urban spaces | W22: • Less cargo flexibility than crossovers • Lower seating hip point for ingress • Fewer AWD options | X22: A well-proportioned high-perf compact sedan offering superior driving manners and efficiency over conventional crossovers. | Y22: https://hips.hearstapps.com/hmg-prod/images/2026-audi-rs3.jpg | Z22: https://www.caranddriver.com/audi/rs3 | AA22: Car and Driver 10Best
A23: 2026 | B23: Audi | C23: A5 | D23: Sedan Premium Plus | E23: Compact Executive Sedan | F23: Mild Hybrid | G23: 49000 | H23: 268 | I23: 295 | J23: 2.0L Turbo I4 48V | K23: 2 | L23: 4 | M23: 7-Speed Dual-Clutch | N23: quattro AWD | O23: 28 (24/33) | P23: N/A | Q23: N/A | R23: 5 | S23: 12 | T23: N/A | U23: 9.0/10 | V23: • Superb real-world fuel economy • Smooth electric-gas power handover • No range anxiety on long trips | W23: • Added curb weight from battery packs • Slightly compromised cargo space • eCVT engine flare during passing | X23: A finely engineered mild hybrid compact executive sedan striking the optimal balance between high efficiency and long-distance practicality. | Y23: https://hips.hearstapps.com/hmg-prod/images/2026-audi-a5.jpg | Z23: https://www.caranddriver.com/audi/a5 | AA23: Car and Driver First Look
A24: 2026 | B24: Audi | C24: S5 | D24: Sedan Prestige | E24: Sport Executive Sedan | F24: Mild Hybrid | G24: 64000 | H24: 362 | I24: 406 | J24: 3.0L Turbo V6 48V | K24: 3 | L24: 6 | M24: 7-Speed Dual-Clutch | N24: quattro AWD | O24: 24 (21/29) | P24: N/A | Q24: N/A | R24: 5 | S24: 12 | T24: N/A | U24: 9.0/10 | V24: • Superb real-world fuel economy • Smooth electric-gas power handover • No range anxiety on long trips | W24: • Added curb weight from battery packs • Slightly compromised cargo space • eCVT engine flare during passing | X24: A finely engineered mild hybrid sport executive sedan striking the optimal balance between high efficiency and long-distance practicality. | Y24: https://hips.hearstapps.com/hmg-prod/images/2026-audi-s5.jpg | Z24: https://www.caranddriver.com/audi/s5 | AA24: Car and Driver First Look
A25: 2026 | B25: Audi | C25: A6 | D25: 55 TFSI quattro | E25: Executive Sedan | F25: Mild Hybrid | G25: 62000 | H25: 335 | I25: 369 | J25: 3.0L Turbo V6 | K25: 3 | L25: 6 | M25: 7-Speed DSG | N25: quattro AWD | O25: 24 (21/30) | P25: N/A | Q25: N/A | R25: 5 | S25: 13.7 | T25: N/A | U25: 8.5/10 | V25: • Superb real-world fuel economy • Smooth electric-gas power handover • No range anxiety on long trips | W25: • Added curb weight from battery packs • Slightly compromised cargo space • eCVT engine flare during passing | X25: A finely engineered mild hybrid executive sedan striking the optimal balance between high efficiency and long-distance practicality. | Y25: https://hips.hearstapps.com/hmg-prod/images/2026-audi-a6.jpg | Z25: https://www.caranddriver.com/audi/a6 | AA25: Car and Driver Buyer's Guide
A26: 2026 | B26: Audi | C26: S6 | D26: Premium Plus | E26: Performance Sedan | F26: Mild Hybrid | G26: 76000 | H26: 444 | I26: 442 | J26: 2.9L Twin-Turbo V6 | K26: 2.9 | L26: 6 | M26: 8-Speed Auto | N26: quattro AWD | O26: 22 (19/26) | P26: N/A | Q26: N/A | R26: 5 | S26: 13.7 | T26: N/A | U26: 8.5/10 | V26: • Superb real-world fuel economy • Smooth electric-gas power handover • No range anxiety on long trips | W26: • Added curb weight from battery packs • Slightly compromised cargo space • eCVT engine flare during passing | X26: A finely engineered mild hybrid performance sedan striking the optimal balance between high efficiency and long-distance practicality. | Y26: https://hips.hearstapps.com/hmg-prod/images/2026-audi-s6.jpg | Z26: https://www.caranddriver.com/audi/s6 | AA26: Car and Driver Buyer's Guide
A27: 2026 | B27: Audi | C27: A6 e-tron | D27: Performance quattro | E27: Executive EV Sedan | F27: Electric | G27: 75000 | H27: 456 | I27: 520 | J27: Dual Electric Motors | K27: N/A | L27: 0 | M27: 1-Speed Direct | N27: quattro AWD | O27: 95 MPGe | P27: 380 | Q27: 100 | R27: 5 | S27: 18 | T27: N/A | U27: 9.0/10 | V27: • Silent, instantaneous acceleration • Low center of gravity enhances stability • Zero tailpipe emissions | W27: • Highway range drops at sustained speed • Public charging network variability • Pricier initial purchase cost | X27: A compelling electric entry in the executive ev sedan segment offering smooth power delivery and advanced tech. | Y27: https://hips.hearstapps.com/hmg-prod/images/2026-audi-a6-e-tron.jpg | Z27: https://www.caranddriver.com/audi/a6-e-tron | AA27: Car and Driver Preview
A28: 2026 | B28: Audi | C28: RS6 Avant | D28: Performance GT | E28: Performance Wagon | F28: Mild Hybrid | G28: 128895 | H28: 621 | I28: 627 | J28: 4.0L Twin-Turbo V8 | K28: 4 | L28: 8 | M28: 8-Speed Auto | N28: quattro AWD | O28: 17 (14/21) | P28: N/A | Q28: N/A | R28: 5 | S28: 30 | T28: N/A | U28: 10/10 | V28: • Superb real-world fuel economy • Smooth electric-gas power handover • No range anxiety on long trips | W28: • Added curb weight from battery packs • Slightly compromised cargo space • eCVT engine flare during passing | X28: A finely engineered mild hybrid performance wagon striking the optimal balance between high efficiency and long-distance practicality. | Y28: https://hips.hearstapps.com/hmg-prod/images/2026-audi-rs6-avant.jpg | Z28: https://www.caranddriver.com/audi/rs6-avant | AA28: Car and Driver 10Best
A29: 2026 | B29: Audi | C29: A7 | D29: 55 TFSI quattro | E29: Luxury Sportback | F29: Mild Hybrid | G29: 73000 | H29: 335 | I29: 369 | J29: 3.0L Turbo V6 | K29: 3 | L29: 6 | M29: 7-Speed DSG | N29: quattro AWD | O29: 24 (21/30) | P29: N/A | Q29: N/A | R29: 5 | S29: 24.9 | T29: N/A | U29: 9.0/10 | V29: • Superb real-world fuel economy • Smooth electric-gas power handover • No range anxiety on long trips | W29: • Added curb weight from battery packs • Slightly compromised cargo space • eCVT engine flare during passing | X29: A finely engineered mild hybrid luxury sportback striking the optimal balance between high efficiency and long-distance practicality. | Y29: https://hips.hearstapps.com/hmg-prod/images/2026-audi-a7.jpg | Z29: https://www.caranddriver.com/audi/a7 | AA29: Car and Driver Editors' Choice
A30: 2026 | B30: Audi | C30: RS7 | D30: Performance | E30: Super Sportback | F30: Mild Hybrid | G30: 129000 | H30: 621 | I30: 627 | J30: 4.0L Twin-Turbo V8 | K30: 4 | L30: 8 | M30: 8-Speed Auto | N30: quattro AWD | O30: 17 (14/21) | P30: N/A | Q30: N/A | R30: 5 | S30: 24.9 | T30: N/A | U30: 9.5/10 | V30: • Superb real-world fuel economy • Smooth electric-gas power handover • No range anxiety on long trips | W30: • Added curb weight from battery packs • Slightly compromised cargo space • eCVT engine flare during passing | X30: A finely engineered mild hybrid super sportback striking the optimal balance between high efficiency and long-distance practicality. | Y30: https://hips.hearstapps.com/hmg-prod/images/2026-audi-rs7.jpg | Z30: https://www.caranddriver.com/audi/rs7 | AA30: Car and Driver Editors' Choice
A31: 2026 | B31: Audi | C31: A8 | D31: 55 TFSI quattro | E31: Full-Size Luxury Flagship | F31: Mild Hybrid | G31: 92000 | H31: 335 | I31: 369 | J31: 3.0L Turbo V6 | K31: 3 | L31: 6 | M31: 8-Speed Auto | N31: quattro AWD | O31: 22 (19/28) | P31: N/A | Q31: N/A | R31: 5 | S31: 12.5 | T31: N/A | U31: 8.5/10 | V31: • Superb real-world fuel economy • Smooth electric-gas power handover • No range anxiety on long trips | W31: • Added curb weight from battery packs • Slightly compromised cargo space • eCVT engine flare during passing | X31: A finely engineered mild hybrid full-size luxury flagship striking the optimal balance between high efficiency and long-distance practicality. | Y31: https://hips.hearstapps.com/hmg-prod/images/2026-audi-a8.jpg | Z31: https://www.caranddriver.com/audi/a8 | AA31: Car and Driver Buyer's Guide
A32: 2026 | B32: Audi | C32: S8 | D32: Base | E32: Performance Flagship Sedan | F32: Mild Hybrid | G32: 126000 | H32: 563 | I32: 590 | J32: 4.0L Twin-Turbo V8 | K32: 4 | L32: 8 | M32: 8-Speed Auto | N32: quattro AWD | O32: 18 (15/24) | P32: N/A | Q32: N/A | R32: 5 | S32: 12.5 | T32: N/A | U32: 9.0/10 | V32: • Superb real-world fuel economy • Smooth electric-gas power handover • No range anxiety on long trips | W32: • Added curb weight from battery packs • Slightly compromised cargo space • eCVT engine flare during passing | X32: A finely engineered mild hybrid performance flagship sedan striking the optimal balance between high efficiency and long-distance practicality. | Y32: https://hips.hearstapps.com/hmg-prod/images/2026-audi-s8.jpg | Z32: https://www.caranddriver.com/audi/s8 | AA32: Car and Driver Editors' Choice
A33: 2026 | B33: Audi | C33: Q3 | D33: 45 TFSI Premium | E33: Subcompact Luxury Crossover | F33: Gasoline | G33: 42000 | H33: 228 | I33: 258 | J33: 2.0L Turbo I4 | K33: 2 | L33: 4 | M33: 8-Speed Auto | N33: quattro AWD | O33: 24 (21/28) | P33: N/A | Q33: N/A | R33: 5 | S33: 23.7 | T33: 2200 | U33: 8.0/10 | V33: • Spacious passenger and cargo room • Commanding elevated driving position • Confidence-inspiring all-weather grip | W33: • Higher center of gravity than sedans • Fuel consumption under heavy load • Less engaging steering feel | X33: A highly versatile subcompact luxury crossover that delivers generous space, modern safety tech, and daily utility. | Y33: https://hips.hearstapps.com/hmg-prod/images/2026-audi-q3.jpg | Z33: https://www.caranddriver.com/audi/q3 | AA33: Car and Driver Buyer's Guide
A34: 2026 | B34: Audi | C34: Q4 e-tron | D34: 55 quattro | E34: Compact EV SUV | F34: Electric | G34: 56500 | H34: 335 | I34: 402 | J34: Dual Electric Motors | K34: N/A | L34: 0 | M34: 1-Speed Direct | N34: quattro AWD | O34: 97 MPGe | P34: 258 | Q34: 82 | R34: 5 | S34: 24.8 | T34: 2600 | U34: 8.0/10 | V34: • Silent, instantaneous acceleration • Low center of gravity enhances stability • Zero tailpipe emissions | W34: • Highway range drops at sustained speed • Public charging network variability • Pricier initial purchase cost | X34: A compelling electric entry in the compact ev suv segment offering smooth power delivery and advanced tech. | Y34: https://hips.hearstapps.com/hmg-prod/images/2026-audi-q4-e-tron.jpg | Z34: https://www.caranddriver.com/audi/q4-e-tron | AA34: Car and Driver Buyer's Guide
A35: 2026 | B35: Audi | C35: Q5 | D35: 45 TFSI Premium | E35: Compact Luxury SUV | F35: Mild Hybrid | G35: 48000 | H35: 268 | I35: 295 | J35: 2.0L Turbo I4 | K35: 2 | L35: 4 | M35: 7-Speed DSG | N35: quattro AWD | O35: 26 (23/29) | P35: N/A | Q35: N/A | R35: 5 | S35: 25.8 | T35: 4400 | U35: 8.5/10 | V35: • Superb real-world fuel economy • Smooth electric-gas power handover • No range anxiety on long trips | W35: • Added curb weight from battery packs • Slightly compromised cargo space • eCVT engine flare during passing | X35: A finely engineered mild hybrid compact luxury suv striking the optimal balance between high efficiency and long-distance practicality. | Y35: https://hips.hearstapps.com/hmg-prod/images/2026-audi-q5.jpg | Z35: https://www.caranddriver.com/audi/q5 | AA35: Car and Driver Buyer's Guide
A36: 2026 | B36: Audi | C36: SQ5 | D36: Prestige | E36: Sport Compact SUV | F36: Mild Hybrid | G36: 66000 | H36: 362 | I36: 406 | J36: 3.0L Turbo V6 | K36: 3 | L36: 6 | M36: 7-Speed DSG | N36: quattro AWD | O36: 22 (19/25) | P36: N/A | Q36: N/A | R36: 5 | S36: 25.8 | T36: 4400 | U36: 8.5/10 | V36: • Superb real-world fuel economy • Smooth electric-gas power handover • No range anxiety on long trips | W36: • Added curb weight from battery packs • Slightly compromised cargo space • eCVT engine flare during passing | X36: A finely engineered mild hybrid sport compact suv striking the optimal balance between high efficiency and long-distance practicality. | Y36: https://hips.hearstapps.com/hmg-prod/images/2026-audi-sq5.jpg | Z36: https://www.caranddriver.com/audi/sq5 | AA36: Car and Driver Buyer's Guide
A37: 2026 | B37: Audi | C37: Q6 e-tron | D37: quattro Premium Plus | E37: Compact Luxury EV SUV | F37: Electric | G37: 67395 | H37: 456 | I37: 428 | J37: Dual Electric Motors | K37: N/A | L37: 0 | M37: 1-Speed Direct | N37: quattro AWD | O37: 90 MPGe | P37: 307 | Q37: 100 | R37: 5 | S37: 30.2 | T37: 4400 | U37: 9.0/10 | V37: • Silent, instantaneous acceleration • Low center of gravity enhances stability • Zero tailpipe emissions | W37: • Highway range drops at sustained speed • Public charging network variability • Pricier initial purchase cost | X37: A compelling electric entry in the compact luxury ev suv segment offering smooth power delivery and advanced tech. | Y37: https://hips.hearstapps.com/hmg-prod/images/2026-audi-q6-e-tron.jpg | Z37: https://www.caranddriver.com/audi/q6-e-tron | AA37: Car and Driver First Drive
A38: 2026 | B38: Audi | C38: Q7 | D38: 55 TFSI Prestige | E38: 3-Row Luxury SUV | F38: Mild Hybrid | G38: 69800 | H38: 335 | I38: 369 | J38: 3.0L Turbo V6 | K38: 3 | L38: 6 | M38: 8-Speed Auto | N38: quattro AWD | O38: 20 (18/23) | P38: N/A | Q38: N/A | R38: 7 | S38: 14.2 | T38: 7000 | U38: 8.5/10 | V38: • Superb real-world fuel economy • Smooth electric-gas power handover • No range anxiety on long trips | W38: • Added curb weight from battery packs • Slightly compromised cargo space • eCVT engine flare during passing | X38: A finely engineered mild hybrid 3-row luxury suv striking the optimal balance between high efficiency and long-distance practicality. | Y38: https://hips.hearstapps.com/hmg-prod/images/2026-audi-q7.jpg | Z38: https://www.caranddriver.com/audi/q7 | AA38: Car and Driver Buyer's Guide
A39: 2026 | B39: Audi | C39: Q8 | D39: 55 TFSI Prestige | E39: Mid-Size Luxury SUV | F39: Mild Hybrid | G39: 76000 | H39: 335 | I39: 369 | J39: 3.0L Turbo V6 | K39: 3 | L39: 6 | M39: 8-Speed Auto | N39: quattro AWD | O39: 19 (17/23) | P39: N/A | Q39: N/A | R39: 5 | S39: 30.5 | T39: 7700 | U39: 8.5/10 | V39: • Superb real-world fuel economy • Smooth electric-gas power handover • No range anxiety on long trips | W39: • Added curb weight from battery packs • Slightly compromised cargo space • eCVT engine flare during passing | X39: A finely engineered mild hybrid mid-size luxury suv striking the optimal balance between high efficiency and long-distance practicality. | Y39: https://hips.hearstapps.com/hmg-prod/images/2026-audi-q8.jpg | Z39: https://www.caranddriver.com/audi/q8 | AA39: Car and Driver Buyer's Guide
A40: 2026 | B40: Audi | C40: RS Q8 | D40: Performance | E40: Super SUV | F40: Mild Hybrid | G40: 137000 | H40: 631 | I40: 627 | J40: 4.0L Twin-Turbo V8 | K40: 4 | L40: 8 | M40: 8-Speed Auto | N40: quattro AWD | O40: 15 (13/19) | P40: N/A | Q40: N/A | R40: 5 | S40: 30.5 | T40: 7700 | U40: 9.0/10 | V40: • Superb real-world fuel economy • Smooth electric-gas power handover • No range anxiety on long trips | W40: • Added curb weight from battery packs • Slightly compromised cargo space • eCVT engine flare during passing | X40: A finely engineered mild hybrid super suv striking the optimal balance between high efficiency and long-distance practicality. | Y40: https://hips.hearstapps.com/hmg-prod/images/2026-audi-rs-q8.jpg | Z40: https://www.caranddriver.com/audi/rs-q8 | AA40: Car and Driver Editors' Choice
...

Sheet Executive Summary & Analytics
A1: US Automotive Market Master Analytics & Segment Distribution
A3: Market Overview KPI Indicators | D3: Powertrain Propulsion Mix
A4: Indicator Metric | B4: Aggregate Value | D4: Powertrain Classification | E4: Vehicle Count
A5: Total Documented US Vehicle Models | B5: =COUNTA('Master 2026-2027 US Catalog'!A4:A458) | D5: Gasoline | E5: =COUNTIF('Master 2026-2027 US Catalog'!F4:F458, "Gasoline")
A6: Average Vehicle MSRP | B6: =AVERAGE('Master 2026-2027 US Catalog'!G4:G458) | D6: Electric | E6: =COUNTIF('Master 2026-2027 US Catalog'!F4:F458, "Electric")
A7: Minimum Vehicle MSRP | B7: =MIN('Master 2026-2027 US Catalog'!G4:G458) | D7: Gas-Electric Hybrid | E7: =COUNTIF('Master 2026-2027 US Catalog'!F4:F458, "Gas-Electric Hybrid")
A8: Maximum Vehicle MSRP | B8: =MAX('Master 2026-2027 US Catalog'!G4:G458) | D8: PHEV | E8: =COUNTIF('Master 2026-2027 US Catalog'!F4:F458, "PHEV")
A9: Average Horsepower Output | B9: =AVERAGE('Master 2026-2027 US Catalog'!H4:H458) | D9: Mild Hybrid | E9: =COUNTIF('Master 2026-2027 US Catalog'!F4:F458, "Mild Hybrid")
A10: Maximum Horsepower Output | B10: =MAX('Master 2026-2027 US Catalog'!H4:H458)
A11: Average Torque Output | B11: =AVERAGE('Master 2026-2027 US Catalog'!I4:I458)
A14: Manufacturer Representation
A15: Brand / Make | B15: Models Cataloged
A16: Acura | B16: =COUNTIF('Master 2026-2027 US Catalog'!B4:B458, "Acura")
A17: Alfa Romeo | B17: =COUNTIF('Master 2026-2027 US Catalog'!B4:B458, "Alfa Romeo")
A18: Aston Martin | B18: =COUNTIF('Master 2026-2027 US Catalog'!B4:B458, "Aston Martin")
A19: Audi | B19: =COUNTIF('Master 2026-2027 US Catalog'!B4:B458, "Audi")
A20: BMW | B20: =COUNTIF('Master 2026-2027 US Catalog'!B4:B458, "BMW")
A21: Bentley | B21: =COUNTIF('Master 2026-2027 US Catalog'!B4:B458, "Bentley")
A22: Buick | B22: =COUNTIF('Master 2026-2027 US Catalog'!B4:B458, "Buick")
A23: Cadillac | B23: =COUNTIF('Master 2026-2027 US Catalog'!B4:B458, "Cadillac")
A24: Chevrolet | B24: =COUNTIF('Master 2026-2027 US Catalog'!B4:B458, "Chevrolet")
A25: Chrysler | B25: =COUNTIF('Master 2026-2027 US Catalog'!B4:B458, "Chrysler")
A26: Dodge | B26: =COUNTIF('Master 2026-2027 US Catalog'!B4:B458, "Dodge")
A27: Ferrari | B27: =COUNTIF('Master 2026-2027 US Catalog'!B4:B458, "Ferrari")
A28: Fiat | B28: =COUNTIF('Master 2026-2027 US Catalog'!B4:B458, "Fiat")
A29: Ford | B29: =COUNTIF('Master 2026-2027 US Catalog'!B4:B458, "Ford")
A30: GMC | B30: =COUNTIF('Master 2026-2027 US Catalog'!B4:B458, "GMC")
A31: Genesis | B31: =COUNTIF('Master 2026-2027 US Catalog'!B4:B458, "Genesis")
A32: Honda | B32: =COUNTIF('Master 2026-2027 US Catalog'!B4:B458, "Honda")
A33: Hyundai | B33: =COUNTIF('Master 2026-2027 US Catalog'!B4:B458, "Hyundai")
A34: Infiniti | B34: =COUNTIF('Master 2026-2027 US Catalog'!B4:B458, "Infiniti")
A35: Jaguar | B35: =COUNTIF('Master 2026-2027 US Catalog'!B4:B458, "Jaguar")
A36: Jeep | B36: =COUNTIF('Master 2026-2027 US Catalog'!B4:B458, "Jeep")
A37: Kia | B37: =COUNTIF('Master 2026-2027 US Catalog'!B4:B458, "Kia")
A38: Lamborghini | B38: =COUNTIF('Master 2026-2027 US Catalog'!B4:B458, "Lamborghini")
A39: Land Rover | B39: =COUNTIF('Master 2026-2027 US Catalog'!B4:B458, "Land Rover")
A40: Lexus | B40: =COUNTIF('Master 2026-2027 US Catalog'!B4:B458, "Lexus")
A41: Lincoln | B41: =COUNTIF('Master 2026-2027 US Catalog'!B4:B458, "Lincoln")
A42: Lotus | B42: =COUNTIF('Master 2026-2027 US Catalog'!B4:B458, "Lotus")
A43: Lucid | B43: =COUNTIF('Master 2026-2027 US Catalog'!B4:B458, "Lucid")
...
